Workbook

Sheet Vendas 2026 - APP
A1: Data | B1: CPF | C1: Cliente | D1: Nome do Cliente Emissor Bemol On-line | E1: Endereço de e-mail | F1: Data de Nascimento | G1: Categoria do Bemol Run | H1: Modalidades do Bemol Run | I1: Bemol Run Genero | J1: Tamanho das camisetas | K1: Tipo de pagamento | L1: Valor do Pedido | M1: Status | N1: EventId | O1: Evento
A2: 46140 | B2: 03638638260 | C2: 2436398 | D2: RAFAEL RIBEIRO BATISTA | E2: rafael37qq@gmail.com | F2: 35501 | G2: GERAL | H2: 5KM | I2: M | J2: GG | K2: CB | L2: 129.9 | M2: INSCRITO | N2: bemol-run-mao-2026_1 | O2: =IF(N2="bemol-run-mao-2026_1", "Manaus", IF(N2="bemol-run-rbr-2026_1", "Rio Branco", IF(N2="bemol-run-pvh-2026_1", "Porto Velho", IF(N2="bemol-run-bvb-2026_1", "Boa Vista", N2)))) -> Manaus
A3: 46140 | B3: 83484965215 | C3: 3697815 | D3: ROMULO HENRIQUE DA SILVA LIMA | E3: iromulo181@gmail.com | F3: 30999 | G3: GERAL | H3: 5KM | I3: F | J3: XG | K3: CB | L3: 129.9 | M3: INSCRITO | N3: bemol-run-mao-2026_1 | O3: =IF(N3="bemol-run-mao-2026_1", "Manaus", IF(N3="bemol-run-rbr-2026_1", "Rio Branco", IF(N3="bemol-run-pvh-2026_1", "Porto Velho", IF(N3="bemol-run-bvb-2026_1", "Boa Vista", N3)))) -> Manaus
A4: 46140 | B4: 96365862253 | C4: 2038651 | D4: ALESSANDRA DE LIMA OLIVEIRA | E4: alessandralima711@gmail.com | F4: 32787 | G4: GERAL | H4: 5KM | I4: F | J4: M | K4: CB | L4: 129.9 | M4: INSCRITO | N4: bemol-run-mao-2026_1 | O4: =IF(N4="bemol-run-mao-2026_1", "Manaus", IF(N4="bemol-run-rbr-2026_1", "Rio Branco", IF(N4="bemol-run-pvh-2026_1", "Porto Velho", IF(N4="bemol-run-bvb-2026_1", "Boa Vista", N4)))) -> Manaus
A5: 46140 | B5: 03114208266 | C5: 2433958 | D5: RUAN CARLOS SANTOS PANTOJA | E5: carlosruanruan@outlook.com | F5: 35815 | G5: GERAL | H5: 10KM | I5: F | J5: PP | K5: CB | L5: 149.9 | M5: INSCRITO | N5: bemol-run-mao-2026_1 | O5: =IF(N5="bemol-run-mao-2026_1", "Manaus", IF(N5="bemol-run-rbr-2026_1", "Rio Branco", IF(N5="bemol-run-pvh-2026_1", "Porto Velho", IF(N5="bemol-run-bvb-2026_1", "Boa Vista", N5)))) -> Manaus
A6: 46140 | B6: 01949743241 | C6: 1903972 | D6: JULLYENNE LIMA CAMPELO | E6: jullyennelima.campelo@gmail.com | F6: 34438 | G6: COLAB | H6: 5KM | I6: F | J6: G | K6: CB | L6: 129.9 | M6: INSCRITO | N6: bemol-run-mao-2026_1 | O6: =IF(N6="bemol-run-mao-2026_1", "Manaus", IF(N6="bemol-run-rbr-2026_1", "Rio Branco", IF(N6="bemol-run-pvh-2026_1", "Porto Velho", IF(N6="bemol-run-bvb-2026_1", "Boa Vista", N6)))) -> Manaus
A7: 46140 | B7: 02746108259 | C7: 2068839 | D7: LETICIA DA SILVA | E7: leticiasilv0901@gmail.com | F7: 35073 | G7: GERAL | H7: 5KM | I7: F | J7: XG | K7: CB | L7: 129.9 | M7: INSCRITO | N7: bemol-run-mao-2026_1 | O7: =IF(N7="bemol-run-mao-2026_1", "Manaus", IF(N7="bemol-run-rbr-2026_1", "Rio Branco", IF(N7="bemol-run-pvh-2026_1", "Porto Velho", IF(N7="bemol-run-bvb-2026_1", "Boa Vista", N7)))) -> Manaus
A8: 46140 | B8: 92009735234 | C8: 1287641 | D8: BIANCA BITENCOURT DA ROCHA | E8: biancabittencourtt@gmail.com | F8: 32997 | G8: COLAB | H8: 5KM | I8: F | J8: P | K8: PIX | L8: 129.9 | M8: INSCRITO | N8: bemol-run-mao-2026_1 | O8: =IF(N8="bemol-run-mao-2026_1", "Manaus", IF(N8="bemol-run-rbr-2026_1", "Rio Branco", IF(N8="bemol-run-pvh-2026_1", "Porto Velho", IF(N8="bemol-run-bvb-2026_1", "Boa Vista", N8)))) -> Manaus
A9: 46140 | B9: 44128177253 | C9: 202062 | D9: DRAYTON HELIO GUERRA DA SILVA | E9: draytonguerra@gmail.com | F9: 26549 | G9: GERAL | H9: 5KM | I9: M | J9: G | K9: CB | L9: 129.9 | M9: INSCRITO | N9: bemol-run-mao-2026_1 | O9: =IF(N9="bemol-run-mao-2026_1", "Manaus", IF(N9="bemol-run-rbr-2026_1", "Rio Branco", IF(N9="bemol-run-pvh-2026_1", "Porto Velho", IF(N9="bemol-run-bvb-2026_1", "Boa Vista", N9)))) -> Manaus
A10: 46140 | B10: 05245774208 | C10: 3897134 | D10: TAINARA CRUZ DA SILVA | E10: taycruz424242@gmail.com | F10: 37158 | G10: COLAB | H10: 5KM | I10: F | J10: M | K10: CB | L10: 129.9 | M10: INSCRITO | N10: bemol-run-mao-2026_1 | O10: =IF(N10="bemol-run-mao-2026_1", "Manaus", IF(N10="bemol-run-rbr-2026_1", "Rio Branco", IF(N10="bemol-run-pvh-2026_1", "Porto Velho", IF(N10="bemol-run-bvb-2026_1", "Boa Vista", N10)))) -> Manaus
A11: 46140 | B11: 00553147242 | C11: 1311577 | D11: LIDIANE MUNHOZ DA SILVEIRA | E11: lidiane.msilveira@hotmail.com | F11: 33229 | G11: GERAL | H11: 5KM | I11: F | J11: P | K11: CB | L11: 129.9 | M11: INSCRITO | N11: bemol-run-mao-2026_1 | O11: =IF(N11="bemol-run-mao-2026_1", "Manaus", IF(N11="bemol-run-rbr-2026_1", "Rio Branco", IF(N11="bemol-run-pvh-2026_1", "Porto Velho", IF(N11="bemol-run-bvb-2026_1", "Boa Vista", N11)))) -> Manaus
A12: 46140 | B12: 00820537233 | D12: GUSTAVO DE ALMEIDA COSTA | E12: gustavocostaalmeida@gmail.com | F12: 35720 | G12: COLAB | H12: 5KM | I12: M | J12: G | K12: PIX | L12: 129.9 | M12: CANCELADO | N12: bemol-run-mao-2026_1 | O12: =IF(N12="bemol-run-mao-2026_1", "Manaus", IF(N12="bemol-run-rbr-2026_1", "Rio Branco", IF(N12="bemol-run-pvh-2026_1", "Porto Velho", IF(N12="bemol-run-bvb-2026_1", "Boa Vista", N12)))) -> Manaus
A13: 46140 | B13: 11658580613 | D13: TAIANNE VALERIE ALVES MOTTA | E13: taiannemotta@gmail.com | F13: 35011 | G13: COLAB | H13: 10KM | I13: M | J13: M | K13: PIX | L13: 129.9 | M13: CANCELADO | N13: bemol-run-rbr-2026_1 | O13: =IF(N13="bemol-run-mao-2026_1", "Manaus", IF(N13="bemol-run-rbr-2026_1", "Rio Branco", IF(N13="bemol-run-pvh-2026_1", "Porto Velho", IF(N13="bemol-run-bvb-2026_1", "Boa Vista", N13)))) -> Rio Branco
A14: 46140 | B14: 07548772211 | C14: 4673140 | D14: JOELSON SILVA MARTINS | E14: mjoelson.martins22@gmail.com | F14: 38409 | G14: GERAL | H14: 10KM | I14: M | J14: G | K14: CB | L14: 129.9 | M14: INSCRITO | N14: bemol-run-mao-2026_1 | O14: =IF(N14="bemol-run-mao-2026_1", "Manaus", IF(N14="bemol-run-rbr-2026_1", "Rio Branco", IF(N14="bemol-run-pvh-2026_1", "Porto Velho", IF(N14="bemol-run-bvb-2026_1", "Boa Vista", N14)))) -> Manaus
A15: 46140 | B15: 00589689207 | C15: 1747043 | D15: AIMEE GOMES DA PENHA MARIA | E15: aimeegpm@gmail.com | F15: 32910 | G15: COLAB | H15: 10KM | I15: F | J15: P | K15: PIX | L15: 129.9 | M15: INSCRITO | N15: bemol-run-mao-2026_1 | O15: =IF(N15="bemol-run-mao-2026_1", "Manaus", IF(N15="bemol-run-rbr-2026_1", "Rio Branco", IF(N15="bemol-run-pvh-2026_1", "Porto Velho", IF(N15="bemol-run-bvb-2026_1", "Boa Vista", N15)))) -> Manaus
A16: 46140 | B16: 70063771292 | C16: 2508055 | D16: MARCOS SOUZA DIAS | E16: marcossouzadias.50@gmail.com | F16: 36308 | G16: GERAL | H16: 5KM | I16: M | J16: M | K16: CB | L16: 129.9 | M16: INSCRITO | N16: bemol-run-mao-2026_1 | O16: =IF(N16="bemol-run-mao-2026_1", "Manaus", IF(N16="bemol-run-rbr-2026_1", "Rio Branco", IF(N16="bemol-run-pvh-2026_1", "Porto Velho", IF(N16="bemol-run-bvb-2026_1", "Boa Vista", N16)))) -> Manaus
A17: 46140 | B17: 70529494230 | C17: 4366151 | D17: KIMBERLY MORAES RIBEIRO | E17: kimberlyribeiro678@gmail.com | F17: 37672 | G17: GERAL | H17: 5KM | I17: F | J17: PP | K17: PIX | L17: 129.9 | M17: INSCRITO | N17: bemol-run-mao-2026_1 | O17: =IF(N17="bemol-run-mao-2026_1", "Manaus", IF(N17="bemol-run-rbr-2026_1", "Rio Branco", IF(N17="bemol-run-pvh-2026_1", "Porto Velho", IF(N17="bemol-run-bvb-2026_1", "Boa Vista", N17)))) -> Manaus
A18: 46140 | B18: 02626761257 | D18: VINICIUS FONTOURA BATISTA | E18: viniciusfontourabatista@hotmail.com | F18: 36711 | G18: GERAL | H18: 10KM | I18: M | J18: M | K18: PIX | L18: 149.9 | M18: CANCELADO | N18: bemol-run-pvh-2026_1 | O18: =IF(N18="bemol-run-mao-2026_1", "Manaus", IF(N18="bemol-run-rbr-2026_1", "Rio Branco", IF(N18="bemol-run-pvh-2026_1", "Porto Velho", IF(N18="bemol-run-bvb-2026_1", "Boa Vista", N18)))) -> Porto Velho
A19: 46140 | B19: 85886181253 | C19: 1134138 | D19: ARGELLY ZAIDEM SANTANA DOS SANTOS | E19: argellyzaidem@bemol.com.br | F19: 31290 | G19: COLAB | H19: 5KM | I19: F | J19: P | K19: CB | L19: 129.9 | M19: INSCRITO | N19: bemol-run-mao-2026_1 | O19: =IF(N19="bemol-run-mao-2026_1", "Manaus", IF(N19="bemol-run-rbr-2026_1", "Rio Branco", IF(N19="bemol-run-pvh-2026_1", "Porto Velho", IF(N19="bemol-run-bvb-2026_1", "Boa Vista", N19)))) -> Manaus
A20: 46140 | B20: 02899967240 | D20: ANTONIO ALBERTO DE SOUZA BARBOSA | E20: antonioalbertodsb@gmail.com | F20: 36346 | G20: COLAB | H20: 10KM | I20: F | J20: G | K20: PIX | L20: 129.9 | M20: CANCELADO | N20: bemol-run-bvb-2026_1 | O20: =IF(N20="bemol-run-mao-2026_1", "Manaus", IF(N20="bemol-run-rbr-2026_1", "Rio Branco", IF(N20="bemol-run-pvh-2026_1", "Porto Velho", IF(N20="bemol-run-bvb-2026_1", "Boa Vista", N20)))) -> Boa Vista
A21: 46140 | B21: 02949034292 | D21: KATIANE AMARANTE CABRAL | E21: katiiane.cabral@gmail.com | F21: 36159 | G21: GERAL | H21: 5KM | I21: F | J21: PP | K21: PIX | L21: 149.9 | M21: CANCELADO | N21: bemol-run-pvh-2026_1 | O21: =IF(N21="bemol-run-mao-2026_1", "Manaus", IF(N21="bemol-run-rbr-2026_1", "Rio Branco", IF(N21="bemol-run-pvh-2026_1", "Porto Velho", IF(N21="bemol-run-bvb-2026_1", "Boa Vista", N21)))) -> Porto Velho
A22: 46140 | B22: 75413639287 | C22: 2077277 | D22: MAURICIO XAVIER TEIXEIRA | E22: mauricioteixeira@bemol.com.br | F22: 30861 | G22: COLAB | H22: 5KM | I22: M | J22: M | K22: CB | L22: 129.9 | M22: INSCRITO | N22: bemol-run-mao-2026_1 | O22: =IF(N22="bemol-run-mao-2026_1", "Manaus", IF(N22="bemol-run-rbr-2026_1", "Rio Branco", IF(N22="bemol-run-pvh-2026_1", "Porto Velho", IF(N22="bemol-run-bvb-2026_1", "Boa Vista", N22)))) -> Manaus
A23: 46140 | B23: 00827504241 | D23: TIAGO ALMEIDA DOS SANTOS | E23: tiagoalmeida@bemol.com.br | F23: 36773 | G23: COLAB | H23: 10KM | I23: M | J23: PP | K23: PIX | L23: 129.9 | M23: CANCELADO | N23: bemol-run-mao-2026_1 | O23: =IF(N23="bemol-run-mao-2026_1", "Manaus", IF(N23="bemol-run-rbr-2026_1", "Rio Branco", IF(N23="bemol-run-pvh-2026_1", "Porto Velho", IF(N23="bemol-run-bvb-2026_1", "Boa Vista", N23)))) -> Manaus
A24: 46140 | B24: 03490528409 | D24: CHRISTIAN BARNADD DANNIELL GOMES E | E24: barnaddmanaus@gmail.com | F24: 29286 | G24: GERAL | H24: 5KM | I24: F | J24: PP | K24: PIX | L24: 149.9 | M24: CANCELADO | N24: bemol-run-bvb-2026_1 | O24: =IF(N24="bemol-run-mao-2026_1", "Manaus", IF(N24="bemol-run-rbr-2026_1", "Rio Branco", IF(N24="bemol-run-pvh-2026_1", "Porto Velho", IF(N24="bemol-run-bvb-2026_1", "Boa Vista", N24)))) -> Boa Vista
A25: 46140 | B25: 00820537233 | D25: GUSTAVO DE ALMEIDA COSTA | E25: gustavocostaalmeida@gmail.com | F25: 35720 | G25: COLAB | H25: 5KM | I25: M | J25: G | K25: PIX | L25: 129.9 | M25: CANCELADO | N25: bemol-run-pvh-2026_1 | O25: =IF(N25="bemol-run-mao-2026_1", "Manaus", IF(N25="bemol-run-rbr-2026_1", "Rio Branco", IF(N25="bemol-run-pvh-2026_1", "Porto Velho", IF(N25="bemol-run-bvb-2026_1", "Boa Vista", N25)))) -> Porto Velho
A26: 46140 | B26: 03281503209 | C26: 2214363 | D26: LICIANE MESQUITA FILGUEIRA | E26: licianeleandro2@gmail.com | F26: 35106 | G26: GERAL | H26: 10KM | I26: F | J26: M | K26: CB | L26: 129.9 | M26: INSCRITO | N26: bemol-run-mao-2026_1 | O26: =IF(N26="bemol-run-mao-2026_1", "Manaus", IF(N26="bemol-run-rbr-2026_1", "Rio Branco", IF(N26="bemol-run-pvh-2026_1", "Porto Velho", IF(N26="bemol-run-bvb-2026_1", "Boa Vista", N26)))) -> Manaus
A27: 46140 | B27: 03482573255 | D27: ANA PAULA CASSIANO DA SILVA | E27: mc.marmed@gmail.com | F27: 34588 | G27: GERAL | H27: 5KM | I27: F | J27: XG | K27: PIX | L27: 149.9 | M27: CANCELADO | N27: bemol-run-mao-2026_1 | O27: =IF(N27="bemol-run-mao-2026_1", "Manaus", IF(N27="bemol-run-rbr-2026_1", "Rio Branco", IF(N27="bemol-run-pvh-2026_1", "Porto Velho", IF(N27="bemol-run-bvb-2026_1", "Boa Vista", N27)))) -> Manaus
A28: 46140 | B28: 02875521284 | C28: 1889603 | D28: DANDARA ERENDIRA DE SOUZA | E28: dandara.ere@gmail.com | F28: 35324 | G28: COLAB | H28: 5KM | I28: M | J28: P | K28: CB | L28: 129.9 | M28: INSCRITO | N28: bemol-run-pvh-2026_1 | O28: =IF(N28="bemol-run-mao-2026_1", "Manaus", IF(N28="bemol-run-rbr-2026_1", "Rio Branco", IF(N28="bemol-run-pvh-2026_1", "Porto Velho", IF(N28="bemol-run-bvb-2026_1", "Boa Vista", N28)))) -> Porto Velho
A29: 46140 | B29: 03003024280 | C29: 4796339 | D29: IGOR KALIEL DE OLIVEIRA MARQUES | E29: igorkaliel6@gmail.com | F29: 38082 | G29: GERAL | H29: 5KM | I29: M | J29: P | K29: CB | L29: 129.9 | M29: INSCRITO | N29: bemol-run-pvh-2026_1 | O29: =IF(N29="bemol-run-mao-2026_1", "Manaus", IF(N29="bemol-run-rbr-2026_1", "Rio Branco", IF(N29="bemol-run-pvh-2026_1", "Porto Velho", IF(N29="bemol-run-bvb-2026_1", "Boa Vista", N29)))) -> Porto Velho
A30: 46140 | B30: 01615936238 | C30: 1743909 | D30: LETICIA RODRIGUES DE MELO | E30: la2057324@icloud.com | F30: 33399 | G30: GERAL | H30: 10KM | I30: F | J30: PP | K30: CB | L30: 129.9 | M30: INSCRITO | N30: bemol-run-pvh-2026_1 | O30: =IF(N30="bemol-run-mao-2026_1", "Manaus", IF(N30="bemol-run-rbr-2026_1", "Rio Branco", IF(N30="bemol-run-pvh-2026_1", "Porto Velho", IF(N30="bemol-run-bvb-2026_1", "Boa Vista", N30)))) -> Porto Velho
A31: 46140 | B31: 00842969250 | C31: 2088638 | D31: CHARLOTE MORAES BRACHER | E31: chachabracher@hotmail.com | F31: 32993 | G31: GERAL | H31: 5KM | I31: M | J31: M | K31: CB | L31: 149.9 | M31: INSCRITO | N31: bemol-run-mao-2026_1 | O31: =IF(N31="bemol-run-mao-2026_1", "Manaus", IF(N31="bemol-run-rbr-2026_1", "Rio Branco", IF(N31="bemol-run-pvh-2026_1", "Porto Velho", IF(N31="bemol-run-bvb-2026_1", "Boa Vista", N31)))) -> Manaus
A32: 46140 | B32: 02949034292 | C32: 3708453 | D32: KATIANE AMARANTE CABRAL | E32: katiiane.cabral@gmail.com | F32: 36159 | G32: GERAL | H32: 5KM | I32: F | J32: PP | K32: CB | L32: 149.9 | M32: INSCRITO | N32: bemol-run-rbr-2026_1 | O32: =IF(N32="bemol-run-mao-2026_1", "Manaus", IF(N32="bemol-run-rbr-2026_1", "Rio Branco", IF(N32="bemol-run-pvh-2026_1", "Porto Velho", IF(N32="bemol-run-bvb-2026_1", "Boa Vista", N32)))) -> Rio Branco
A33: 46140 | B33: 51342294220 | C33: 1896919 | D33: ADRIANA COSTA RAMIRES | E33: adriianeramires@hotmail.com | F33: 28527 | G33: GERAL | H33: 10KM | I33: M | J33: P | K33: CB | L33: 129.9 | M33: INSCRITO | N33: bemol-run-mao-2026_1 | O33: =IF(N33="bemol-run-mao-2026_1", "Manaus", IF(N33="bemol-run-rbr-2026_1", "Rio Branco", IF(N33="bemol-run-pvh-2026_1", "Porto Velho", IF(N33="bemol-run-bvb-2026_1", "Boa Vista", N33)))) -> Manaus
A34: 46140 | B34: 98407465291 | C34: 2564566 | D34: TILARA MOURA LOPES | E34: tilara.lopes@gmail.com | F34: 33814 | G34: COLAB | H34: 5KM | I34: F | J34: M | K34: CB | L34: 129.9 | M34: INSCRITO | N34: bemol-run-mao-2026_1 | O34: =IF(N34="bemol-run-mao-2026_1", "Manaus", IF(N34="bemol-run-rbr-2026_1", "Rio Branco", IF(N34="bemol-run-pvh-2026_1", "Porto Velho", IF(N34="bemol-run-bvb-2026_1", "Boa Vista", N34)))) -> Manaus
A35: 46140 | B35: 02949034292 | C35: 3708453 | D35: KATIANE AMARANTE CABRAL | E35: katiiane.cabral@gmail.com | F35: 36159 | G35: GERAL | H35: 5KM | I35: F | J35: PP | K35: CB | L35: 149.9 | M35: INSCRITO | N35: bemol-run-pvh-2026_1 | O35: =IF(N35="bemol-run-mao-2026_1", "Manaus", IF(N35="bemol-run-rbr-2026_1", "Rio Branco", IF(N35="bemol-run-pvh-2026_1", "Porto Velho", IF(N35="bemol-run-bvb-2026_1", "Boa Vista", N35)))) -> Porto Velho
A36: 46140 | B36: 53162706220 | C36: 1239268 | D36: VITOR AZEVEDO DE SOUZA | E36: vitorsouza84@icloud.com | F36: 32626 | G36: GERAL | H36: 10KM | I36: M | J36: P | K36: PIX | L36: 129.9 | M36: INSCRITO | N36: bemol-run-pvh-2026_1 | O36: =IF(N36="bemol-run-mao-2026_1", "Manaus", IF(N36="bemol-run-rbr-2026_1", "Rio Branco", IF(N36="bemol-run-pvh-2026_1", "Porto Velho", IF(N36="bemol-run-bvb-2026_1", "Boa Vista", N36)))) -> Porto Velho
A37: 46140 | B37: 01466440260 | C37: 2400031 | D37: THAIS EMANUELLE CARVALHO DA SILVA | E37: thaissilva@bemol.com.br | F37: 35660 | G37: COLAB | H37: 5KM | I37: F | J37: P | K37: CB | L37: 129.9 | M37: INSCRITO | N37: bemol-run-mao-2026_1 | O37: =IF(N37="bemol-run-mao-2026_1", "Manaus", IF(N37="bemol-run-rbr-2026_1", "Rio Branco", IF(N37="bemol-run-pvh-2026_1", "Porto Velho", IF(N37="bemol-run-bvb-2026_1", "Boa Vista", N37)))) -> Manaus
A38: 46140 | B38: 02530352283 | C38: 2312984 | D38: LARISSA SILVA PONTE | E38: lariissasilva_@hotmail.com | F38: 34873 | G38: GERAL | H38: 5KM | I38: F | J38: P | K38: CB | L38: 149.9 | M38: INSCRITO | N38: bemol-run-pvh-2026_1 | O38: =IF(N38="bemol-run-mao-2026_1", "Manaus", IF(N38="bemol-run-rbr-2026_1", "Rio Branco", IF(N38="bemol-run-pvh-2026_1", "Porto Velho", IF(N38="bemol-run-bvb-2026_1", "Boa Vista", N38)))) -> Porto Velho
A39: 46140 | B39: 00653862210 | C39: 2683242 | D39: BRENDA MORAES SANTOS | E39: brendamsantos@hotmail.com | F39: 34556 | G39: GERAL | H39: 5KM | I39: F | J39: P | K39: CB | L39: 149.9 | M39: INSCRITO | N39: bemol-run-pvh-2026_1 | O39: =IF(N39="bemol-run-mao-2026_1", "Manaus", IF(N39="bemol-run-rbr-2026_1", "Rio Branco", IF(N39="bemol-run-pvh-2026_1", "Porto Velho", IF(N39="bemol-run-bvb-2026_1", "Boa Vista", N39)))) -> Porto Velho
... A49: 46140 | B49: 99086964249 | C49: 1662504 | D49: TAINA LOPES MONTEIRO | E49: taina_rox@hotmail.com | F49: 39570 | G49: GERAL | H49: 10KM | I49: M | J49: P | K49: CB | L49: 149.9 | M49: INSCRITO | N49: bemol-run-pvh-2026_1 | O49: =IF(N49="bemol-run-mao-2026_1", "Manaus", IF(N49="bemol-run-rbr-2026_1", "Rio Branco", IF(N49="bemol-run-pvh-2026_1", "Porto Velho", IF(N49="bemol-run-bvb-2026_1", "Boa Vista", N49)))) -> Porto Velho
...

Sheet Vendas - Tickets
A1: numeroPedido | B1: dataPedido | C1: status | D1: formaDePagamento | E1: idEvento | F1: tituloEvento | G1: realizacao | H1: inscricao_grupo | I1: inscricao | J1: nome | K1: documento | L1: email | M1: celular | N1: sexo | O1: nascimento | P1: categoria | Q1: modalidade | R1: valorUnitario | S1: valorTaxa | T1: valorDesconto | U1: valorRepasse | V1: cep | W1: endereco | X1: numero | Y1: bairro | Z1: cidade | AA1: estado | AB1: pais | AC1: camiseta_5km | AD1: camiseta_10km | AE1: camiseta_kids | AF1: camisetas | AG1: responsavel | AH1: emailResponsavel | AI1: documentoResponsavel
A2: 12485139 | B2: 23/04/2026 17:54 | C2: Cancelado | D2: Started | E2: 86645 | F2: Manaus | G2: 30/08/2026 | H2: FALSE | I2: 15252914 | J2: Louise Silva | K2: 02711568210 | L2: louisebaptista96@hotmail.com | M2: 5592993032059 | N2: F | O2: 08/11/1996 | P2: KIT PARTICIPAÇÃO | Q2: 5KM | R2: 149,90 | S2: 14,99 | T2: 0,00 | U2: 149,90 | V2: 69058122 | W2: Rua Almirante | X2: 22C | Y2: Parque 10 | Z2: Manaus | AA2: AM | AB2: Brasil | AC2: P | AF2: P | AG2: Louise Silva | AH2: louisebaptista96@hotmail.com | AI2: 02711568210
A3: 12521816 | B3: 28/04/2026 11:53 | C3: Pago | D3: Pix | E3: 86647 | F3: Porto Velho | G3: 26/07/2026 | H3: FALSE | I3: 15295574 | J3: Luciana Ermita | K3: 92746187191 | L3: luoliveira2309@gmail.com | M3: 5569981700508 | N3: F | O3: 23/09/1978 | P3: KIT PARTICIPAÇÃO | Q3: 5KM | R3: 149,90 | S3: 14,99 | T3: 0,00 | U3: 149,90 | V3: 76820294 | W3: Rua Reverendo Elias Fontes | X3: 1714 | Y3: Agenor de carvalho | Z3: Porto Velho | AA3: RO | AB3: Brasil | AC3: G | AF3: G | AG3: Carlos Eduardo Ermita | AH3: ermita260144@gmail.com | AI3: 36146323187
A4: 12521816 | B4: 28/04/2026 11:53 | C4: Pago | D4: Pix | E4: 86647 | F4: Porto Velho | G4: 26/07/2026 | H4: FALSE | I4: 15295573 | J4: Carlos Eduardo Ermita | K4: 36146323187 | L4: ermita260144@gmail.com | M4: 5569981158476 | N4: M | O4: 04/04/1970 | P4: KIT PARTICIPAÇÃO | Q4: 10KM | R4: 149,90 | S4: 14,99 | T4: 0,00 | U4: 149,90 | V4: 76820294 | W4: Rua Reverendo Elias Fontes | X4: 1714 | Y4: Agenor de carvalho | Z4: Porto Velho | AA4: RO | AB4: Brasil | AD4: GG | AF4: GG | AG4: Carlos Eduardo Ermita | AH4: ermita260144@gmail.com | AI4: 36146323187
A5: 12524462 | B5: 28/04/2026 14:32 | C5: Cancelado | D5: Started | E5: 86645 | F5: Manaus | G5: 30/08/2026 | H5: FALSE | I5: 15298662 | J5: Larissa Teixeira Maddy | K5: 94690855234 | L5: larissamaddyc@gmail.com | M5: 5592984197246 | N5: F | O5: 14/01/1995 | P5: KIT PARTICIPAÇÃO | Q5: 5KM | R5: 149,90 | S5: 14,99 | T5: 0,00 | U5: 149,90 | V5: 69088390 | W5: Rua Acaete | X5: 3 | Y5: Jorge Teixeira | Z5: Manaus | AA5: AM | AB5: Brasil | AC5: M | AF5: M | AG5: Larissa Teixeira Maddy | AH5: larissamaddyc@gmail.com | AI5: 94690855234
A6: 12524468 | B6: 28/04/2026 14:10 | C6: Pago | D6: Cartão Crédito | E6: 86647 | F6: Porto Velho | G6: 26/07/2026 | H6: FALSE | I6: 15298672 | J6: Carlos Henrique Lustosa Silva | K6: 87112035287 | L6: carloshenriquepvh@gmail.com | M6: 69985018770 | N6: M | O6: 15/04/1989 | P6: KIT PARTICIPAÇÃO | Q6: 10KM | R6: 149,90 | S6: 14,99 | T6: 0,00 | U6: 149,90 | V6: 76812642 | W6: Rua Lirio | X6: 6409 | Y6: Três Marias | Z6: Porto Velho | AA6: RO | AB6: Brasil | AD6: M | AF6: M | AG6: Carlos Henrique Lustosa Silva | AH6: carloshenriquepvh@gmail.com | AI6: 87112035287
A7: 12524505 | B7: 28/04/2026 14:37 | C7: Pago | D7: Cartão Crédito | E7: 86647 | F7: Porto Velho | G7: 26/07/2026 | H7: FALSE | I7: 15298714 | J7: Sabrina Alves Pereira Valerio | K7: 01850084297 | L7: salvespereiravalerio@gmail.com | M7: 5569992322374 | N7: F | O7: 03/11/1992 | P7: KIT PARTICIPAÇÃO | Q7: 5KM | R7: 149,90 | S7: 14,99 | T7: 0,00 | U7: 149,90 | V7: 76860000 | W7: Rua Duarte Da Costa | X7: 287 | Y7: União | Z7: Candeias do Jamari | AA7: RO | AB7: Brasil | AC7: P | AF7: P | AG7: Sabrina Alves Pereira Valerio | AH7: salvespereiravalerio@gmail.com | AI7: 01850084297
A8: 12524512 | B8: 28/04/2026 14:58 | C8: Pago | D8: Pix | E8: 86647 | F8: Porto Velho | G8: 26/07/2026 | H8: FALSE | I8: 15298722 | J8: Lidia De Azevedo Jaghoub | K8: 00992415284 | L8: lidiaazevedo@outlook.com | M8: 5569993943388 | N8: F | O8: 21/11/2000 | P8: KIT PARTICIPAÇÃO | Q8: 10KM | R8: 149,90 | S8: 14,99 | T8: 0,00 | U8: 149,90 | V8: 76801492 | W8: Rua Jamary | X8: 1823 | Y8: pedrinhas | Z8: Porto Velho | AA8: RO | AB8: Brasil | AD8: PP | AF8: PP | AG8: Lidia De Azevedo Jaghoub | AH8: lidiaazevedo@outlook.com | AI8: 00992415284
A9: 12524548 | B9: 28/04/2026 14:03 | C9: Cancelado | D9: Started | E9: 86647 | F9: Porto Velho | G9: 26/07/2026 | H9: FALSE | I9: 15298768 | J9: Flavia Barbosa Riela Cavalcante | K9: 85782742291 | L9: cafeparisro@gmail.com | M9: 5569993440047 | N9: F | O9: 23/04/1984 | P9: KIT PARTICIPAÇÃO | Q9: 5KM | R9: 149,90 | S9: 14,99 | T9: 0,00 | U9: 149,90 | Z9: Porto Velho | AA9: RO | AB9: Brasil | AC9: P | AF9: P | AG9: Leandro Da Silva Cavalcante | AH9: leandrosilvasil007@gmail.com | AI9: 02529638225
A10: 12524551 | B10: 28/04/2026 14:22 | C10: Pago | D10: Cartão Crédito | E10: 86645 | F10: Manaus | G10: 30/08/2026 | H10: FALSE | I10: 15298772 | J10: Claudia Rejane Facanha | K10: 55945538272 | L10: claudia.rejane1907@gmail.com | M10: 92992253847 | N10: F | O10: 09/07/1974 | P10: KIT PARTICIPAÇÃO | Q10: 5KM | R10: 149,90 | S10: 14,99 | T10: 0,00 | U10: 149,90 | V10: 69060020 | W10: Avenida Ephigênio Salles | X10: 1835 | Y10: Aleixo | Z10: Manaus | AA10: AM | AB10: Brasil | AC10: P | AF10: P | AG10: Adenor De Lima | AH10: adenor.lima33@gmail.com | AI10: 19277237287
A11: 12524551 | B11: 28/04/2026 14:22 | C11: Pago | D11: Cartão Crédito | E11: 86645 | F11: Manaus | G11: 30/08/2026 | H11: FALSE | I11: 15298771 | J11: Adenor De Lima | K11: 19277237287 | L11: adenor.lima33@gmail.com | M11: 92981339951 | N11: M | O11: 12/08/1964 | P11: KIT PARTICIPAÇÃO | Q11: 5KM | R11: 149,90 | S11: 7,50 | T11: 74,95 | U11: 74,95 | V11: 69060020 | W11: Avenida Ephigênio Salles | X11: 1835 | Y11: Aleixo | Z11: Manaus | AA11: AM | AB11: Brasil | AC11: M | AF11: M | AG11: Adenor De Lima | AH11: adenor.lima33@gmail.com | AI11: 19277237287
A12: 12524562 | B12: 28/04/2026 14:42 | C12: Pago | D12: Pix | E12: 86645 | F12: Manaus | G12: 30/08/2026 | H12: FALSE | I12: 15298786 | J12: Gustavo Turner | K12: 33202180851 | L12: gustavoturner@hotmail.com | N12: M | O12: 30/12/1981 | P12: KIT PARTICIPAÇÃO | Q12: 10KM | R12: 149,90 | S12: 14,99 | T12: 0,00 | U12: 149,90 | V12: 69054238 | W12: Rua Heisei | X12: 321 | Y12: Parque 10 de Novembro | Z12: Manaus | AA12: AM | AB12: Brasil | AD12: G | AF12: G | AG12: Gustavo Turner | AH12: gustavoturner@hotmail.com | AI12: 33202180851
A13: 12524572 | B13: 28/04/2026 14:42 | C13: Cancelado | D13: Started | E13: 86647 | F13: Porto Velho | G13: 26/07/2026 | H13: FALSE | I13: 15298797 | J13: Lucas Varnou Da Silva | K13: 00459663208 | L13: l.varnou@gmail.com | M13: 5569993684011 | N13: M | O13: 05/09/1990 | P13: KIT PARTICIPAÇÃO | Q13: 10KM | R13: 149,90 | S13: 14,99 | T13: 0,00 | U13: 149,90 | V13: 76817001 | W13: Rua Jardins | X13: 114 | Y13: Bairro novo | Z13: Porto Velho | AA13: RO | AB13: Brasil | AD13: M | AF13: M | AG13: Lucas Varnou Da Silva | AH13: l.varnou@gmail.com | AI13: 00459663208
A14: 12524658 | B14: 28/04/2026 14:46 | C14: Cancelado | D14: Started | E14: 86647 | F14: Porto Velho | G14: 26/07/2026 | H14: FALSE | I14: 15298889 | J14: Noel Leite Da Silva | K14: 52095223268 | L14: noelleitedasilva@hotmail.com | M14: 5569984314545 | N14: M | O14: 29/01/1982 | P14: KIT PARTICIPAÇÃO | Q14: 5KM | R14: 149,90 | S14: 14,99 | T14: 0,00 | U14: 149,90 | V14: 76.821460 | W14: Casa | X14: 4670 | Y14: Rio Madeira | Z14: Porto Velho | AA14: RO | AB14: Brasil | AC14: XG | AF14: XG | AG14: Noel Leite Da Silva | AH14: noelleitedasilva@hotmail.com | AI14: 52095223268
A15: 12524659 | B15: 28/04/2026 14:09 | C15: Cancelado | D15: Started | E15: 86645 | F15: Manaus | G15: 30/08/2026 | H15: FALSE | I15: 15298890 | J15: Luciana Maria Pinheiro De Freitas | K15: 66416671204 | L15: lmcpinheiro@gmail.com | M15: 5592981118966 | N15: F | O15: 04/04/1981 | P15: KIT PARTICIPAÇÃO | Q15: 5KM | R15: 149,90 | S15: 14,99 | T15: 0,00 | U15: 149,90 | V15: 69083120 | W15: Rua Nelson Batista De Sales | X15: 01 | Y15: Aleixo | Z15: Manaus | AA15: AM | AB15: Brasil | AC15: M | AF15: M | AG15: Luciana Maria Pinheiro De Freitas | AH15: lmcpinheiro@gmail.com | AI15: 66416671204
A16: 12524669 | B16: 28/04/2026 14:55 | C16: Cancelado | D16: Started | E16: 86647 | F16: Porto Velho | G16: 26/07/2026 | H16: FALSE | I16: 15298900 | J16: Luciana Martins De Matos | K16: 84688700210 | L16: mluciana012@gmail.com | M16: 5569993561848 | N16: F | O16: 27/08/1983 | P16: KIT PARTICIPAÇÃO | Q16: 5KM | R16: 149,90 | S16: 14,99 | T16: 0,00 | U16: 149,90 | V16: 76860000 | W16: Rua Rio Branco | X16: 608 | Y16: União | Z16: Candeias do Jamari | AA16: RO | AB16: Brasil | AC16: P | AF16: P | AG16: Luciana Martins De Matos | AH16: mluciana012@gmail.com | AI16: 84688700210
A17: 12524679 | B17: 28/04/2026 14:07 | C17: Pago | D17: Cartão Crédito/Mastercard | E17: 86645 | F17: Manaus | G17: 30/08/2026 | H17: FALSE | I17: 15298915 | J17: Alexsandro Silva Souza | K17: 84289244220 | L17: x.sandro.souza@gmail.com | M17: 5592981477164 | N17: M | O17: 06/08/1986 | P17: KIT PARTICIPAÇÃO | Q17: 10KM | R17: 149,90 | S17: 14,99 | T17: 0,00 | U17: 149,90 | Z17: Manaus | AA17: AM | AB17: Brasil | AD17: M | AF17: M | AG17: Patricia Silva Souza | AH17: patty8044@hotmail.com | AI17: 74251791215
A18: 12524679 | B18: 28/04/2026 14:07 | C18: Pago | D18: Cartão Crédito/Mastercard | E18: 86645 | F18: Manaus | G18: 30/08/2026 | H18: FALSE | I18: 15298914 | J18: Patricia Silva Souza | K18: 74251791215 | L18: patty8044@hotmail.com | M18: 92991251520 | N18: F | O18: 24/03/1983 | P18: KIT PARTICIPAÇÃO | Q18: 10KM | R18: 149,90 | S18: 14,99 | T18: 0,00 | U18: 149,90 | Z18: Manaus | AA18: AM | AB18: Brasil | AD18: M | AF18: M | AG18: Patricia Silva Souza | AH18: patty8044@hotmail.com | AI18: 74251791215
A19: 12524708 | B19: 28/04/2026 14:00 | C19: Cancelado | D19: Started | E19: 86645 | F19: Manaus | G19: 30/08/2026 | H19: FALSE | I19: 15298946 | J19: Marcilene De Moraes Ferreira | K19: 36976970215 | L19: marcilenedmoraes@gmail.com | M19: 5592981275414 | N19: F | O19: 13/03/1970 | P19: KIT PARTICIPAÇÃO | Q19: 5KM | R19: 149,90 | S19: 14,99 | T19: 0,00 | U19: 149,90 | V19: 69097772 | W19: Rua Flora Rica | X19: 13 | Y19: Nova Cidade | Z19: Manaus | AA19: AM | AB19: Brasil | AC19: P | AF19: P | AG19: Marcilene De Moraes Ferreira | AH19: marcilenedmoraes@gmail.com | AI19: 36976970215
A20: 12524729 | B20: 28/04/2026 14:04 | C20: Pago | D20: Pix | E20: 86647 | F20: Porto Velho | G20: 26/07/2026 | H20: FALSE | I20: 15298970 | J20: Gecelia Do Socorro David Silva Macedo | K20: 63255189268 | L20: geceliamacedo@gmail.com | M20: 5569992728353 | N20: F | O20: 02/10/1978 | P20: KIT PARTICIPAÇÃO | Q20: 5KM | R20: 149,90 | S20: 14,99 | T20: 0,00 | U20: 149,90 | V20: 76824082 | W20: Rua Paulo Fortes | X20: 6308 | Y20: Aponiã | Z20: Porto Velho | AA20: RO | AB20: Brasil | AC20: G | AF20: G | AG20: Gecelia Do Socorro David Silva Macedo | AH20: geceliamacedo@gmail.com | AI20: 63255189268
A21: 12524729 | B21: 28/04/2026 14:04 | C21: Pago | D21: Pix | E21: 86647 | F21: Porto Velho | G21: 26/07/2026 | H21: FALSE | I21: 15298971 | J21: Humberto Junior Macedo Passos | K21: 18326382272 | L21: hjunior1322@gmail.com | M21: 5569993315474 | N21: M | O21: 10/01/1966 | P21: KIT PARTICIPAÇÃO | Q21: 5KM | R21: 149,90 | S21: 7,50 | T21: 74,95 | U21: 74,95 | V21: 76824082 | W21: Rua Paulo Fortes | X21: 6308 | Y21: Aponiã | Z21: Porto Velho | AA21: RO | AB21: Brasil | AC21: G | AF21: G | AG21: Gecelia Do Socorro David Silva Macedo | AH21: geceliamacedo@gmail.com | AI21: 63255189268
A22: 12524763 | B22: 28/04/2026 15:31 | C22: Cancelado | D22: Cartão Crédito/Mastercard | E22: 86647 | F22: Porto Velho | G22: 26/07/2026 | H22: FALSE | I22: 15299012 | J22: Ana Carolina Monteiro De Souza | K22: 02694846203 | L22: carolcla153@gmail.com | M22: 5569992379239 | N22: F | O22: 26/06/1996 | P22: KIT PARTICIPAÇÃO | Q22: 10KM | R22: 149,90 | S22: 14,99 | T22: 0,00 | U22: 149,90 | V22: 76824046 | W22: Paulo Fortes | X22: 6850 | Y22: Aponia | Z22: Porto Velho | AA22: RO | AB22: Brasil | AD22: PP | AF22: PP | AG22: Ana Carolina Monteiro De Souza | AH22: carolcla153@gmail.com | AI22: 02694846203
A23: 12524779 | B23: 28/04/2026 15:31 | C23: Pago | D23: Cartão Crédito/Visa | E23: 86647 | F23: Porto Velho | G23: 26/07/2026 | H23: FALSE | I23: 15299040 | J23: Wanderlea Lessa Mariaca | K23: 22099883220 | L23: wlmariaca@hotmail.com | M23: 69999843016 | N23: F | O23: 05/10/1966 | P23: KIT PARTICIPAÇÃO | Q23: 10KM | R23: 149,90 | S23: 7,50 | T23: 74,95 | U23: 74,95 | V23: 76803814 | W23: Rua Francisco Fonseca | X23: 1736 | Y23: São João Bosco | Z23: Porto Velho | AA23: RO | AB23: Brasil | AD23: PP | AF23: PP | AG23: Wanderlea Lessa Mariaca | AH23: wlmariaca@hotmail.com | AI23: 22099883220
A24: 12524785 | B24: 28/04/2026 15:57 | C24: Pago | D24: Pix | E24: 86647 | F24: Porto Velho | G24: 26/07/2026 | H24: FALSE | I24: 15299050 | J24: Lucas Varnou Da Silva | K24: 00459663208 | L24: l.varnou@gmail.com | M24: 5569993684011 | N24: M | O24: 05/09/1990 | P24: KIT PARTICIPAÇÃO | Q24: 5KM | R24: 149,90 | S24: 14,99 | T24: 0,00 | U24: 149,90 | V24: 76817001 | W24: Rua Jardins | X24: 114 | Y24: Bairro novo | Z24: Porto Velho | AA24: RO | AB24: Brasil | AC24: M | AF24: M | AG24: Lucas Varnou Da Silva | AH24: l.varnou@gmail.com | AI24: 00459663208
A25: 12524790 | B25: 28/04/2026 15:16 | C25: Cancelado | D25: Started | E25: 86645 | F25: Manaus | G25: 30/08/2026 | H25: FALSE | I25: 15299056 | J25: Leandro Nascimento Simao Filho | K25: 47289643291 | L25: leandrosimao.filho@hotmail.com | M25: 92991444679 | N25: M | O25: 26/10/1975 | P25: KIT PARTICIPAÇÃO | Q25: 10KM | R25: 149,90 | S25: 14,99 | T25: 0,00 | U25: 149,90 | V25: 69036520 | W25: Retiro Santa Luzia | X25: 350 | Y25: Santo Agostinho | Z25: Manaus | AA25: AM | AB25: Brasil | AD25: G | AF25: G | AG25: Leandro Nascimento Simao Filho | AH25: leandrosimao.filho@hotmail.com | AI25: 47289643291
A26: 12524797 | B26: 28/04/2026 15:06 | C26: Cancelado | D26: Started | E26: 86647 | F26: Porto Velho | G26: 26/07/2026 | H26: FALSE | I26: 15299063 | J26: Ivan Eduardo Carvalho Da Silva | K26: 02771531232 | L26: ivaneduardo233@gmail.com | M26: 5569993386672 | N26: M | O26: 01/09/1999 | P26: KIT PARTICIPAÇÃO | Q26: 5KM | R26: 149,90 | S26: 14,99 | T26: 0,00 | U26: 149,90 | V26: 76803892 | W26: Senador Alvaro Maia | X26: 2380 | Y26: São João bosco | Z26: Porto Velho | AA26: RO | AB26: Brasil | AC26: G | AF26: G | AG26: Ivan Eduardo Carvalho Da Silva | AH26: ivaneduardo233@gmail.com | AI26: 02771531232
A27: 12524799 | B27: 28/04/2026 15:21 | C27: Pago | D27: Pix | E27: 86645 | F27: Manaus | G27: 30/08/2026 | H27: FALSE | I27: 15299065 | J27: Rose Mary Silva De Araujo | K27: 24255459215 | L27: lui.dog@hotmail.com | M27: 92981201616 | N27: F | O27: 23/06/1962 | P27: KIT PARTICIPAÇÃO | Q27: 10KM | R27: 149,90 | S27: 7,50 | T27: 74,95 | U27: 74,95 | V27: 69054130 | W27: Rua Rainha Catarina, Conj. Vila Do Rei | X27: 12 | Y27: Parque 10 | Z27: Manaus | AA27: AM | AB27: Brasil | AD27: P | AF27: P | AG27: Rose Mary Silva De Araujo | AH27: lui.dog@hotmail.com | AI27: 24255459215
A28: 12524803 | B28: 28/04/2026 15:53 | C28: Pago | D28: Cartão Crédito | E28: 86645 | F28: Manaus | G28: 30/08/2026 | H28: FALSE | I28: 15299071 | J28: Kellem Da Silva Lopes | K28: 59836571272 | L28: eunice.ozaky@proverconsultores.com.br | M28: 92981339829 | N28: F | O28: 26/08/1977 | P28: KIT PARTICIPAÇÃO | Q28: 5KM | R28: 149,90 | S28: 14,99 | T28: 0,00 | U28: 149,90 | AC28: P | AF28: P | AG28: Eunice Ozaki Lopes Da Rosa | AH28: eunicelopes15@gmail.com | AI28: 34630317287
A29: 12524803 | B29: 28/04/2026 15:53 | C29: Pago | D29: Cartão Crédito | E29: 86645 | F29: Manaus | G29: 30/08/2026 | H29: FALSE | I29: 15299070 | J29: Joao Domingos Da Rosa | K29: 04427984827 | L29: eunice.ozaky@proverconsultores.com.br | M29: 92981339829 | N29: M | O29: 11/11/1962 | P29: KIT PARTICIPAÇÃO | Q29: 5KM | R29: 149,90 | S29: 7,50 | T29: 74,95 | U29: 74,95 | AC29: GG | AF29: GG | AG29: Eunice Ozaki Lopes Da Rosa | AH29: eunicelopes15@gmail.com | AI29: 34630317287
A30: 12524808 | B30: 28/04/2026 15:18 | C30: Pago | D30: Cartão Crédito | E30: 86647 | F30: Porto Velho | G30: 26/07/2026 | H30: FALSE | I30: 15299076 | J30: Rosalina Maria De Oliveira Sevegnani Nicocelli | K30: 40973590297 | L30: nikaanicocelli@gmail.com | M30: 69992150239 | N30: F | O30: 20/04/1973 | P30: KIT PARTICIPAÇÃO | Q30: 10KM | R30: 149,90 | S30: 14,99 | T30: 0,00 | U30: 149,90 | V30: 76803790 | W30: Rua Jose Ferreira Sobrinho | X30: 1604 | Y30: São João Bosco | Z30: Porto Velho | AA30: RO | AB30: Brasil | AD30: P | AF30: P | AG30: Rosalina Maria De Oliveira Sevegnani Nicocelli | AH30: nikaanicocelli@gmail.com | AI30: 40973590297
A31: 12524813 | B31: 28/04/2026 15:42 | C31: Pago | D31: Pix | E31: 86647 | F31: Porto Velho | G31: 26/07/2026 | H31: FALSE | I31: 15299081 | J31: Noel Leite Da Silva | K31: 52095223268 | L31: noelleitedasilva@hotmail.com | M31: 5569984314545 | N31: M | O31: 29/01/1982 | P31: KIT PARTICIPAÇÃO | Q31: 5KM | R31: 149,90 | S31: 14,99 | T31: 0,00 | U31: 149,90 | V31: 76.821460 | W31: Casa | X31: 4670 | Y31: Rio Madeira | Z31: Porto Velho | AA31: RO | AB31: Brasil | AC31: XG | AF31: XG | AG31: Noel Leite Da Silva | AH31: noelleitedasilva@hotmail.com | AI31: 52095223268
A32: 12524820 | B32: 28/04/2026 15:12 | C32: Pago | D32: Cartão Crédito | E32: 86651 | F32: Manaus Kids | G32: 29/08/2026 | H32: FALSE | I32: 15299088 | J32: Marina Carvalho Dib | K32: 09846066295 | L32: amyrdib@gmail.com | M32: 5592981389937 | N32: F | O32: 25/07/2021 | P32: KIT ATLETA | Q32: 100m - 5 a 6 anos | R32: 119,90 | S32: 11,99 | T32: 0,00 | U32: 119,90 | Z32: Manaus | AA32: AM | AB32: Brasil | AE32: 6 anos | AF32: 6 anos | AG32: Amyr Mussa Dib | AH32: amyrdib@gmail.com | AI32: 52803686287
A33: 12524822 | B33: 28/04/2026 15:28 | C33: Pago | D33: Pix | E33: 86647 | F33: Porto Velho | G33: 26/07/2026 | H33: FALSE | I33: 15299090 | J33: Shaiene Costa Silva | K33: 02340870216 | L33: shaienecostapvh@gmail.com | M33: 5569993200123 | N33: F | O33: 10/12/1992 | P33: KIT PARTICIPAÇÃO | Q33: 5KM | R33: 149,90 | S33: 14,99 | T33: 0,00 | U33: 149,90 | V33: 76829532 | W33: Amelia Farias | X33: 3540 | Y33: Tancredo Neves | Z33: Porto Velho | AA33: RO | AB33: Brasil | AC33: GG | AF33: GG | AG33: Shaiene Costa Silva | AH33: shaienecostapvh@gmail.com | AI33: 02340870216
A34: 12524826 | B34: 28/04/2026 15:36 | C34: Cancelado | D34: Pix | E34: 86645 | F34: Manaus | G34: 30/08/2026 | H34: FALSE | I34: 15299095 | J34: Shemilly Da Rocha Mauricio | K34: 04916496221 | L34: shemyrocha@gmail.com | M34: 5592984134231 | N34: F | O34: 23/12/1998 | P34: KIT PARTICIPAÇÃO | Q34: 5KM | R34: 149,90 | S34: 14,99 | T34: 0,00 | U34: 149,90 | V34: 69730000 | W34: Rua Antonio Vinhorte | X34: 154 | Y34: santo elias | Z34: Novo Airão | AA34: AM | AB34: Brasil | AC34: PP | AF34: PP | AG34: Soraia Rodrigues De Souza | AH34: soraiarodrigues833@gmail.com | AI34: 02703566220
A35: 12524831 | B35: 28/04/2026 15:56 | C35: Cancelado | D35: Started | E35: 86647 | F35: Porto Velho | G35: 26/07/2026 | H35: FALSE | I35: 15299101 | J35: Naiara Raquel Silva Carneiro | K35: 81499400225 | L35: naiarasraquel@gmail.com | M35: 5569999194572 | N35: F | O35: 18/09/1984 | P35: KIT PARTICIPAÇÃO | Q35: 5KM | R35: 149,90 | S35: 14,99 | T35: 0,00 | U35: 149,90 | V35: 76820108 | W35: Rua Joao Pedro Da Rocha | X35: 560 | Y35: Nova Porto Velho | Z35: Porto Velho | AA35: RO | AB35: Brasil | AC35: M | AF35: M | AG35: Naiara Raquel Silva Carneiro | AH35: naiarasraquel@gmail.com | AI35: 81499400225
A36: 12524895 | B36: 28/04/2026 15:54 | C36: Cancelado | D36: Started | E36: 86647 | F36: Porto Velho | G36: 26/07/2026 | H36: FALSE | I36: 15299178 | J36: Axelly Ashelley Gama Nobre | K36: 05492065238 | L36: axellyashelley@gmail.com | M36: 5569993839557 | N36: F | O36: 28/02/2007 | P36: KIT PARTICIPAÇÃO | Q36: 5KM | R36: 149,90 | S36: 14,99 | T36: 0,00 | U36: 149,90 | V36: 76824068 | W36: Rua Veleiro | X36: 6207 | Y36: Aponiã | Z36: Porto Velho | AA36: RO | AB36: Brasil | AC36: PP | AF36: PP | AG36: Axelly Ashelley Gama Nobre | AH36: axellyashelley@gmail.com | AI36: 05492065238
A37: 12524918 | B37: 28/04/2026 15:53 | C37: Pago | D37: Pix | E37: 86645 | F37: Manaus | G37: 30/08/2026 | H37: FALSE | I37: 15299206 | J37: Adalberto Ferreira De Oliveira | K37: 13569635287 | L37: adalberto2014@hotmail.com | M37: 81067467 | N37: M | O37: 07/01/1965 | P37: KIT PARTICIPAÇÃO | Q37: 10KM | R37: 149,90 | S37: 7,50 | T37: 74,95 | U37: 74,95 | V37: 69036800 | W37: rua 7 casa 31 quadra10 | X37: 31 | Y37: santo agostinho | Z37: Manaus | AA37: AM | AB37: Brasil | AD37: G | AF37: G | AG37: Bruna Vaneska L Vieira | AH37: bvieira.tam@gmail.com | AI37: 85007323268
A38: 12524921 | B38: 28/04/2026 15:17 | C38: Pago | D38: Pix | E38: 86647 | F38: Porto Velho | G38: 26/07/2026 | H38: FALSE | I38: 15299209 | J38: Ana B C S Moraes | K38: 02092094297 | L38: mad.csmoraes@gmail.com | M38: 5569999048231 | N38: F | O38: 21/08/1992 | P38: KIT PARTICIPAÇÃO | Q38: 5KM | R38: 149,90 | S38: 14,99 | T38: 0,00 | U38: 149,90 | V38: 76821405 | W38: R Eng Anysio Da Rocha Compasso | X38: 2165 | Y38: Rio Madeira | Z38: Porto Velho | AA38: RO | AB38: Brasil | AC38: PP | AF38: PP | AG38: Ana B C S Moraes | AH38: mad.csmoraes@gmail.com | AI38: 02092094297
A39: 12524959 | B39: 28/04/2026 15:19 | C39: Cancelado | D39: Pix | E39: 86647 | F39: Porto Velho | G39: 26/07/2026 | H39: FALSE | I39: 15299264 | J39: Isabeli Facanha | K39: 04489599250 | L39: belifacanha@gmail.com | M39: 5569992948864 | N39: F | O39: 29/01/2009 | P39: KIT PARTICIPAÇÃO | Q39: 5KM | R39: 149,90 | S39: 14,99 | T39: 0,00 | U39: 149,90 | V39: 76821405 | W39: Av. Engenheiro Anysio Da Rocha Compasso | X39: 6021 | Y39: Rio Madeira | Z39: Porto Velho | AA39: RO | AB39: Brasil | AC39: PP | AF39: PP | AG39: Isabeli Facanha | AH39: belifacanha@gmail.com | AI39: 04489599250
A40: 12524967 | B40: 28/04/2026 15:08 | C40: Cancelado | D40: Started | E40: 86645 | F40: Manaus | G40: 30/08/2026 | H40: FALSE | I40: 15299275 | J40: Marcilene Machado Batista | K40: 58829270210 | L40: marcikka.batista@gmail.com | M40: 92985345697 | N40: F | O40: 11/04/1976 | P40: KIT PARTICIPAÇÃO | Q40: 5KM | R40: 149,90 | S40: 14,99 | T40: 0,00 | U40: 149,90 | V40: 69033000 | W40: Avenida São Jorge | X40: 253 | Y40: São Jorge | Z40: Manaus | AA40: AM | AB40: Brasil | AC40: P | AF40: P | AG40: Marcilene Machado Batista | AH40: marcikka.batista@gmail.com | AI40: 58829270210
...

Sheet RESUMO_EVENTOS
A1: Cidade | B1: Estado | C1: Modalidades | D1: Tamanho das camisetas | E1: APP BEMOL - ESTOQUE | F1: TICKETS - ESTOQUE | G1: VENDA APP BEMOL | H1: VENDA TICKETS | I1: SALDO CORTESIA | J1: ESTOQUE CORTESIA | K1: PEDIDO | M1: SALDO APP BEMOL | N1: SALDO TICKET
A2: Rio Branco | B2: AC | C2: 5KM | D2: PP | E2: 99 | F2: 11 | G2: =COUNTIFS('Vendas SAP'!P:P,RESUMO_EVENTOS!A2,'Vendas SAP'!J:J,RESUMO_EVENTOS!C2,'Vendas SAP'!L:L,RESUMO_EVENTOS!D2,'Vendas SAP'!O:O,"INSCRITO") -> 113 | H2: =COUNTIFS('Vendas - Tickets'!F:F,RESUMO_EVENTOS!A2,'Vendas - Tickets'!Q:Q,RESUMO_EVENTOS!C2,'Vendas - Tickets'!AF:AF,RESUMO_EVENTOS!D2,'Vendas - Tickets'!C:C,"Pago") -> 11 | M2: =E2-G2 -> -14 | N2: =F2-H2 -> 0
A3: Rio Branco | B3: AC | C3: 5KM | D3: P | E3: 183 | F3: 40 | G3: =COUNTIFS('Vendas SAP'!P:P,RESUMO_EVENTOS!A3,'Vendas SAP'!J:J,RESUMO_EVENTOS!C3,'Vendas SAP'!L:L,RESUMO_EVENTOS!D3,'Vendas SAP'!O:O,"INSCRITO") -> 265 | H3: =COUNTIFS('Vendas - Tickets'!F:F,RESUMO_EVENTOS!A3,'Vendas - Tickets'!Q:Q,RESUMO_EVENTOS!C3,'Vendas - Tickets'!AF:AF,RESUMO_EVENTOS!D3,'Vendas - Tickets'!C:C,"Pago") -> 28 | M3: =E3-G3 -> -82 | N3: =F3-H3 -> 12
A4: Rio Branco | B4: AC | C4: 5KM | D4: M | E4: 142 | F4: 95 | G4: =COUNTIFS('Vendas SAP'!P:P,RESUMO_EVENTOS!A4,'Vendas SAP'!J:J,RESUMO_EVENTOS!C4,'Vendas SAP'!L:L,RESUMO_EVENTOS!D4,'Vendas SAP'!O:O,"INSCRITO") -> 276 | H4: =COUNTIFS('Vendas - Tickets'!F:F,RESUMO_EVENTOS!A4,'Vendas - Tickets'!Q:Q,RESUMO_EVENTOS!C4,'Vendas - Tickets'!AF:AF,RESUMO_EVENTOS!D4,'Vendas - Tickets'!C:C,"Pago") -> 34 | M4: =E4-G4 -> -134 | N4: =F4-H4 -> 61
A5: Rio Branco | B5: AC | C5: 5KM | D5: G | E5: 120 | F5: 75 | G5: =COUNTIFS('Vendas SAP'!P:P,RESUMO_EVENTOS!A5,'Vendas SAP'!J:J,RESUMO_EVENTOS!C5,'Vendas SAP'!L:L,RESUMO_EVENTOS!D5,'Vendas SAP'!O:O,"INSCRITO") -> 218 | H5: =COUNTIFS('Vendas - Tickets'!F:F,RESUMO_EVENTOS!A5,'Vendas - Tickets'!Q:Q,RESUMO_EVENTOS!C5,'Vendas - Tickets'!AF:AF,RESUMO_EVENTOS!D5,'Vendas - Tickets'!C:C,"Pago") -> 23 | M5: =E5-G5 -> -98 | N5: =F5-H5 -> 52
A6: Rio Branco | B6: AC | C6: 5KM | D6: GG | E6: 53 | F6: 7 | G6: =COUNTIFS('Vendas SAP'!P:P,RESUMO_EVENTOS!A6,'Vendas SAP'!J:J,RESUMO_EVENTOS!C6,'Vendas SAP'!L:L,RESUMO_EVENTOS!D6,'Vendas SAP'!O:O,"INSCRITO") -> 72 | H6: =COUNTIFS('Vendas - Tickets'!F:F,RESUMO_EVENTOS!A6,'Vendas - Tickets'!Q:Q,RESUMO_EVENTOS!C6,'Vendas - Tickets'!AF:AF,RESUMO_EVENTOS!D6,'Vendas - Tickets'!C:C,"Pago") -> 5 | M6: =E6-G6 -> -19 | N6: =F6-H6 -> 2
A7: Rio Branco | B7: AC | C7: 5KM | D7: XG | E7: 27 | F7: 6 | G7: =COUNTIFS('Vendas SAP'!P:P,RESUMO_EVENTOS!A7,'Vendas SAP'!J:J,RESUMO_EVENTOS!C7,'Vendas SAP'!L:L,RESUMO_EVENTOS!D7,'Vendas SAP'!O:O,"INSCRITO") -> 41 | H7: =COUNTIFS('Vendas - Tickets'!F:F,RESUMO_EVENTOS!A7,'Vendas - Tickets'!Q:Q,RESUMO_EVENTOS!C7,'Vendas - Tickets'!AF:AF,RESUMO_EVENTOS!D7,'Vendas - Tickets'!C:C,"Pago") -> 2 | M7: =E7-G7 -> -14 | N7: =F7-H7 -> 4
A8: Rio Branco | B8: AC | C8: 10KM | D8: PP | E8: 26 | F8: 4 | G8: =COUNTIFS('Vendas SAP'!P:P,RESUMO_EVENTOS!A8,'Vendas SAP'!J:J,RESUMO_EVENTOS!C8,'Vendas SAP'!L:L,RESUMO_EVENTOS!D8,'Vendas SAP'!O:O,"INSCRITO") -> 30 | H8: =COUNTIFS('Vendas - Tickets'!F:F,RESUMO_EVENTOS!A8,'Vendas - Tickets'!Q:Q,RESUMO_EVENTOS!C8,'Vendas - Tickets'!AF:AF,RESUMO_EVENTOS!D8,'Vendas - Tickets'!C:C,"Pago") -> 4 | M8: =E8-G8 -> -4 | N8: =F8-H8 -> 0
A9: Rio Branco | B9: AC | C9: 10KM | D9: P | E9: 69 | F9: 11 | G9: =COUNTIFS('Vendas SAP'!P:P,RESUMO_EVENTOS!A9,'Vendas SAP'!J:J,RESUMO_EVENTOS!C9,'Vendas SAP'!L:L,RESUMO_EVENTOS!D9,'Vendas SAP'!O:O,"INSCRITO") -> 82 | H9: =COUNTIFS('Vendas - Tickets'!F:F,RESUMO_EVENTOS!A9,'Vendas - Tickets'!Q:Q,RESUMO_EVENTOS!C9,'Vendas - Tickets'!AF:AF,RESUMO_EVENTOS!D9,'Vendas - Tickets'!C:C,"Pago") -> 11 | M9: =E9-G9 -> -13 | N9: =F9-H9 -> 0
A10: Rio Branco | B10: AC | C10: 10KM | D10: M | E10: 117 | F10: 27 | G10: =COUNTIFS('Vendas SAP'!P:P,RESUMO_EVENTOS!A10,'Vendas SAP'!J:J,RESUMO_EVENTOS!C10,'Vendas SAP'!L:L,RESUMO_EVENTOS!D10,'Vendas SAP'!O:O,"INSCRITO") -> 169 | H10: =COUNTIFS('Vendas - Tickets'!F:F,RESUMO_EVENTOS!A10,'Vendas - Tickets'!Q:Q,RESUMO_EVENTOS!C10,'Vendas - Tickets'!AF:AF,RESUMO_EVENTOS!D10,'Vendas - Tickets'!C:C,"Pago") -> 17 | M10: =E10-G10 -> -52 | N10: =F10-H10 -> 10
A11: Rio Branco | B11: AC | C11: 10KM | D11: G | E11: 87 | F11: 20 | G11: =COUNTIFS('Vendas SAP'!P:P,RESUMO_EVENTOS!A11,'Vendas SAP'!J:J,RESUMO_EVENTOS!C11,'Vendas SAP'!L:L,RESUMO_EVENTOS!D11,'Vendas SAP'!O:O,"INSCRITO") -> 111 | H11: =COUNTIFS('Vendas - Tickets'!F:F,RESUMO_EVENTOS!A11,'Vendas - Tickets'!Q:Q,RESUMO_EVENTOS!C11,'Vendas - Tickets'!AF:AF,RESUMO_EVENTOS!D11,'Vendas - Tickets'!C:C,"Pago") -> 8 | M11: =E11-G11 -> -24 | N11: =F11-H11 -> 12
A12: Rio Branco | B12: AC | C12: 10KM | D12: GG | E12: 17 | F12: 8 | G12: =COUNTIFS('Vendas SAP'!P:P,RESUMO_EVENTOS!A12,'Vendas SAP'!J:J,RESUMO_EVENTOS!C12,'Vendas SAP'!L:L,RESUMO_EVENTOS!D12,'Vendas SAP'!O:O,"INSCRITO") -> 20 | H12: =COUNTIFS('Vendas - Tickets'!F:F,RESUMO_EVENTOS!A12,'Vendas - Tickets'!Q:Q,RESUMO_EVENTOS!C12,'Vendas - Tickets'!AF:AF,RESUMO_EVENTOS!D12,'Vendas - Tickets'!C:C,"Pago") -> 4 | M12: =E12-G12 -> -3 | N12: =F12-H12 -> 4
A13: Rio Branco | B13: AC | C13: 10KM | D13: XG | E13: 9 | F13: 6 | G13: =COUNTIFS('Vendas SAP'!P:P,RESUMO_EVENTOS!A13,'Vendas SAP'!J:J,RESUMO_EVENTOS!C13,'Vendas SAP'!L:L,RESUMO_EVENTOS!D13,'Vendas SAP'!O:O,"INSCRITO") -> 6 | H13: =COUNTIFS('Vendas - Tickets'!F:F,RESUMO_EVENTOS!A13,'Vendas - Tickets'!Q:Q,RESUMO_EVENTOS!C13,'Vendas - Tickets'!AF:AF,RESUMO_EVENTOS!D13,'Vendas - Tickets'!C:C,"Pago") -> 1 | M13: =E13-G13 -> 3 | N13: =F13-H13 -> 5
... A25: Porto Velho | B25: RO | C25: 10KM | D25: XG | E25: 8 | F25: 7 | G25: =COUNTIFS('Vendas SAP'!P:P,RESUMO_EVENTOS!A25,'Vendas SAP'!J:J,RESUMO_EVENTOS!C25,'Vendas SAP'!L:L,RESUMO_EVENTOS!D25,'Vendas SAP'!O:O,"INSCRITO") -> 9 | H25: =COUNTIFS('Vendas - Tickets'!F:F,RESUMO_EVENTOS!A25,'Vendas - Tickets'!Q:Q,RESUMO_EVENTOS!C25,'Vendas - Tickets'!AF:AF,RESUMO_EVENTOS!D25,'Vendas - Tickets'!C:C,"Pago") -> 1 | M25: =E25-G25 -> -1 | N25: =F25-H25 -> 6
A26: Manaus | B26: AM | C26: 5KM | D26: PP | E26: 289 | F26: 71 | G26: =COUNTIFS('Vendas SAP'!P:P,RESUMO_EVENTOS!A26,'Vendas SAP'!J:J,RESUMO_EVENTOS!C26,'Vendas SAP'!L:L,RESUMO_EVENTOS!D26,'Vendas SAP'!O:O,"INSCRITO") -> 365 | H26: =COUNTIFS('Vendas - Tickets'!F:F,RESUMO_EVENTOS!A26,'Vendas - Tickets'!Q:Q,RESUMO_EVENTOS!C26,'Vendas - Tickets'!AF:AF,RESUMO_EVENTOS!D26,'Vendas - Tickets'!C:C,"Pago") -> 69 | M26: =E26-G26 -> -76 | N26: =F26-H26 -> 2 | P26: =M26-(20%*M26) -> -60.8 | Q26: =M26-P26 -> -15.2 | S26: =F26+Q26 -> 55.8
A27: Manaus | B27: AM | C27: 5KM | D27: P | E27: 816 | F27: 123 | G27: =COUNTIFS('Vendas SAP'!P:P,RESUMO_EVENTOS!A27,'Vendas SAP'!J:J,RESUMO_EVENTOS!C27,'Vendas SAP'!L:L,RESUMO_EVENTOS!D27,'Vendas SAP'!O:O,"INSCRITO") -> 1001 | H27: =COUNTIFS('Vendas - Tickets'!F:F,RESUMO_EVENTOS!A27,'Vendas - Tickets'!Q:Q,RESUMO_EVENTOS!C27,'Vendas - Tickets'!AF:AF,RESUMO_EVENTOS!D27,'Vendas - Tickets'!C:C,"Pago") -> 120 | M27: =E27-G27 -> -185 | N27: =F27-H27 -> 3 | P27: 243 | Q27: =M27-P27 -> -428 | S27: =F27+Q27 -> -305
A28: Manaus | B28: AM | C28: 5KM | D28: M | E28: 1301 | F28: 165 | G28: =COUNTIFS('Vendas SAP'!P:P,RESUMO_EVENTOS!A28,'Vendas SAP'!J:J,RESUMO_EVENTOS!C28,'Vendas SAP'!L:L,RESUMO_EVENTOS!D28,'Vendas SAP'!O:O,"INSCRITO") -> 1667 | H28: =COUNTIFS('Vendas - Tickets'!F:F,RESUMO_EVENTOS!A28,'Vendas - Tickets'!Q:Q,RESUMO_EVENTOS!C28,'Vendas - Tickets'!AF:AF,RESUMO_EVENTOS!D28,'Vendas - Tickets'!C:C,"Pago") -> 157 | M28: =E28-G28 -> -366 | N28: =F28-H28 -> 8 | P28: 523 | Q28: =M28-P28 -> -889 | S28: =F28+Q28 -> -724
A29: Manaus | B29: AM | C29: 5KM | D29: G | E29: 709 | F29: 89 | G29: =COUNTIFS('Vendas SAP'!P:P,RESUMO_EVENTOS!A29,'Vendas SAP'!J:J,RESUMO_EVENTOS!C29,'Vendas SAP'!L:L,RESUMO_EVENTOS!D29,'Vendas SAP'!O:O,"INSCRITO") -> 904 | H29: =COUNTIFS('Vendas - Tickets'!F:F,RESUMO_EVENTOS!A29,'Vendas - Tickets'!Q:Q,RESUMO_EVENTOS!C29,'Vendas - Tickets'!AF:AF,RESUMO_EVENTOS!D29,'Vendas - Tickets'!C:C,"Pago") -> 88 | M29: =E29-G29 -> -195 | N29: =F29-H29 -> 1 | P29: 263 | Q29: =M29-P29 -> -458 | S29: =F29+Q29 -> -369
A30: Manaus | B30: AM | C30: 5KM | D30: GG | E30: 126 | F30: 22 | G30: =COUNTIFS('Vendas SAP'!P:P,RESUMO_EVENTOS!A30,'Vendas SAP'!J:J,RESUMO_EVENTOS!C30,'Vendas SAP'!L:L,RESUMO_EVENTOS!D30,'Vendas SAP'!O:O,"INSCRITO") -> 155 | H30: =COUNTIFS('Vendas - Tickets'!F:F,RESUMO_EVENTOS!A30,'Vendas - Tickets'!Q:Q,RESUMO_EVENTOS!C30,'Vendas - Tickets'!AF:AF,RESUMO_EVENTOS!D30,'Vendas - Tickets'!C:C,"Pago") -> 22 | M30: =E30-G30 -> -29 | N30: =F30-H30 -> 0 | P30: 24 | Q30: =M30-P30 -> -53 | S30: =F30+Q30 -> -31
A31: Manaus | B31: AM | C31: 5KM | D31: XG | E31: 58 | F31: 10 | G31: =COUNTIFS('Vendas SAP'!P:P,RESUMO_EVENTOS!A31,'Vendas SAP'!J:J,RESUMO_EVENTOS!C31,'Vendas SAP'!L:L,RESUMO_EVENTOS!D31,'Vendas SAP'!O:O,"INSCRITO") -> 75 | H31: =COUNTIFS('Vendas - Tickets'!F:F,RESUMO_EVENTOS!A31,'Vendas - Tickets'!Q:Q,RESUMO_EVENTOS!C31,'Vendas - Tickets'!AF:AF,RESUMO_EVENTOS!D31,'Vendas - Tickets'!C:C,"Pago") -> 9 | M31: =E31-G31 -> -17 | N31: =F31-H31 -> 1 | P31: 16 | Q31: =M31-P31 -> -33 | S31: =F31+Q31 -> -23
A32: Manaus | B32: AM | C32: 10KM | D32: PP | E32: 112 | F32: 37 | G32: =COUNTIFS('Vendas SAP'!P:P,RESUMO_EVENTOS!A32,'Vendas SAP'!J:J,RESUMO_EVENTOS!C32,'Vendas SAP'!L:L,RESUMO_EVENTOS!D32,'Vendas SAP'!O:O,"INSCRITO") -> 145 | H32: =COUNTIFS('Vendas - Tickets'!F:F,RESUMO_EVENTOS!A32,'Vendas - Tickets'!Q:Q,RESUMO_EVENTOS!C32,'Vendas - Tickets'!AF:AF,RESUMO_EVENTOS!D32,'Vendas - Tickets'!C:C,"Pago") -> 37 | M32: =E32-G32 -> -33 | N32: =F32-H32 -> 0 | P32: 11 | Q32: =M32-P32 -> -44 | S32: =F32+Q32 -> -7
A33: Manaus | B33: AM | C33: 10KM | D33: P | E33: 483 | F33: 73 | G33: =COUNTIFS('Vendas SAP'!P:P,RESUMO_EVENTOS!A33,'Vendas SAP'!J:J,RESUMO_EVENTOS!C33,'Vendas SAP'!L:L,RESUMO_EVENTOS!D33,'Vendas SAP'!O:O,"INSCRITO") -> 615 | H33: =COUNTIFS('Vendas - Tickets'!F:F,RESUMO_EVENTOS!A33,'Vendas - Tickets'!Q:Q,RESUMO_EVENTOS!C33,'Vendas - Tickets'!AF:AF,RESUMO_EVENTOS!D33,'Vendas - Tickets'!C:C,"Pago") -> 70 | M33: =E33-G33 -> -132 | N33: =F33-H33 -> 3 | P33: 211 | Q33: =M33-P33 -> -343 | S33: =F33+Q33 -> -270
A34: Manaus | B34: AM | C34: 10KM | D34: M | E34: 665 | F34: 80 | G34: =COUNTIFS('Vendas SAP'!P:P,RESUMO_EVENTOS!A34,'Vendas SAP'!J:J,RESUMO_EVENTOS!C34,'Vendas SAP'!L:L,RESUMO_EVENTOS!D34,'Vendas SAP'!O:O,"INSCRITO") -> 880 | H34: =COUNTIFS('Vendas - Tickets'!F:F,RESUMO_EVENTOS!A34,'Vendas - Tickets'!Q:Q,RESUMO_EVENTOS!C34,'Vendas - Tickets'!AF:AF,RESUMO_EVENTOS!D34,'Vendas - Tickets'!C:C,"Pago") -> 78 | M34: =E34-G34 -> -215 | N34: =F34-H34 -> 2 | P34: 372 | Q34: =M34-P34 -> -587 | S34: =F34+Q34 -> -507
A35: Manaus | B35: AM | C35: 10KM | D35: G | E35: 412 | F35: 54 | G35: =COUNTIFS('Vendas SAP'!P:P,RESUMO_EVENTOS!A35,'Vendas SAP'!J:J,RESUMO_EVENTOS!C35,'Vendas SAP'!L:L,RESUMO_EVENTOS!D35,'Vendas SAP'!O:O,"INSCRITO") -> 558 | H35: =COUNTIFS('Vendas - Tickets'!F:F,RESUMO_EVENTOS!A35,'Vendas - Tickets'!Q:Q,RESUMO_EVENTOS!C35,'Vendas - Tickets'!AF:AF,RESUMO_EVENTOS!D35,'Vendas - Tickets'!C:C,"Pago") -> 52 | M35: =E35-G35 -> -146 | N35: =F35-H35 -> 2 | P35: 266 | Q35: =M35-P35 -> -412 | S35: =F35+Q35 -> -358
A36: Manaus | B36: AM | C36: 10KM | D36: GG | E36: 65 | F36: 14 | G36: =COUNTIFS('Vendas SAP'!P:P,RESUMO_EVENTOS!A36,'Vendas SAP'!J:J,RESUMO_EVENTOS!C36,'Vendas SAP'!L:L,RESUMO_EVENTOS!D36,'Vendas SAP'!O:O,"INSCRITO") -> 77 | H36: =COUNTIFS('Vendas - Tickets'!F:F,RESUMO_EVENTOS!A36,'Vendas - Tickets'!Q:Q,RESUMO_EVENTOS!C36,'Vendas - Tickets'!AF:AF,RESUMO_EVENTOS!D36,'Vendas - Tickets'!C:C,"Pago") -> 14 | M36: =E36-G36 -> -12 | N36: =F36-H36 -> 0 | P36: 14 | Q36: =M36-P36 -> -26 | S36: =F36+Q36 -> -12
A37: Manaus | B37: AM | C37: 10KM | D37: XG | E37: 13 | F37: 7 | G37: =COUNTIFS('Vendas SAP'!P:P,RESUMO_EVENTOS!A37,'Vendas SAP'!J:J,RESUMO_EVENTOS!C37,'Vendas SAP'!L:L,RESUMO_EVENTOS!D37,'Vendas SAP'!O:O,"INSCRITO") -> 17 | H37: =COUNTIFS('Vendas - Tickets'!F:F,RESUMO_EVENTOS!A37,'Vendas - Tickets'!Q:Q,RESUMO_EVENTOS!C37,'Vendas - Tickets'!AF:AF,RESUMO_EVENTOS!D37,'Vendas - Tickets'!C:C,"Pago") -> 7 | M37: =E37-G37 -> -4 | N37: =F37-H37 -> 0 | P37: 5 | Q37: =M37-P37 -> -9 | S37: =F37+Q37 -> -2
A38: Boa Vista | B38: RR | C38: 5KM | D38: PP | E38: 210 | F38: 30 | G38: =COUNTIFS('Vendas SAP'!P:P,RESUMO_EVENTOS!A38,'Vendas SAP'!J:J,RESUMO_EVENTOS!C38,'Vendas SAP'!L:L,RESUMO_EVENTOS!D38,'Vendas SAP'!O:O,"INSCRITO") -> 210 | H38: =COUNTIFS('Vendas - Tickets'!F:F,RESUMO_EVENTOS!A38,'Vendas - Tickets'!Q:Q,RESUMO_EVENTOS!C38,'Vendas - Tickets'!AF:AF,RESUMO_EVENTOS!D38,'Vendas - Tickets'!C:C,"Pago") -> 16 | M38: =E38-G38 -> 0 | N38: =F38-H38 -> 14
A39: Boa Vista | B39: RR | C39: 5KM | D39: P | E39: 355 | F39: 132 | G39: =COUNTIFS('Vendas SAP'!P:P,RESUMO_EVENTOS!A39,'Vendas SAP'!J:J,RESUMO_EVENTOS!C39,'Vendas SAP'!L:L,RESUMO_EVENTOS!D39,'Vendas SAP'!O:O,"INSCRITO") -> 250 | H39: =COUNTIFS('Vendas - Tickets'!F:F,RESUMO_EVENTOS!A39,'Vendas - Tickets'!Q:Q,RESUMO_EVENTOS!C39,'Vendas - Tickets'!AF:AF,RESUMO_EVENTOS!D39,'Vendas - Tickets'!C:C,"Pago") -> 23 | M39: =E39-G39 -> 105 | N39: =F39-H39 -> 109
A40: Boa Vista | B40: RR | C40: 5KM | D40: M | E40: 271 | F40: 255 | G40: =COUNTIFS('Vendas SAP'!P:P,RESUMO_EVENTOS!A40,'Vendas SAP'!J:J,RESUMO_EVENTOS!C40,'Vendas SAP'!L:L,RESUMO_EVENTOS!D40,'Vendas SAP'!O:O,"INSCRITO") -> 265 | H40: =COUNTIFS('Vendas - Tickets'!F:F,RESUMO_EVENTOS!A40,'Vendas - Tickets'!Q:Q,RESUMO_EVENTOS!C40,'Vendas - Tickets'!AF:AF,RESUMO_EVENTOS!D40,'Vendas - Tickets'!C:C,"Pago") -> 27 | M40: =E40-G40 -> 6 | N40: =F40-H40 -> 228
A41: Boa Vista | B41: RR | C41: 5KM | D41: G | E41: 231 | F41: 262 | G41: =COUNTIFS('Vendas SAP'!P:P,RESUMO_EVENTOS!A41,'Vendas SAP'!J:J,RESUMO_EVENTOS!C41,'Vendas SAP'!L:L,RESUMO_EVENTOS!D41,'Vendas SAP'!O:O,"INSCRITO") -> 165 | H41: =COUNTIFS('Vendas - Tickets'!F:F,RESUMO_EVENTOS!A41,'Vendas - Tickets'!Q:Q,RESUMO_EVENTOS!C41,'Vendas - Tickets'!AF:AF,RESUMO_EVENTOS!D41,'Vendas - Tickets'!C:C,"Pago") -> 8 | M41: =E41-G41 -> 66 | N41: =F41-H41 -> 254
A42: Boa Vista | B42: RR | C42: 5KM | D42: GG | E42: 94 | F42: 50 | G42: =COUNTIFS('Vendas SAP'!P:P,RESUMO_EVENTOS!A42,'Vendas SAP'!J:J,RESUMO_EVENTOS!C42,'Vendas SAP'!L:L,RESUMO_EVENTOS!D42,'Vendas SAP'!O:O,"INSCRITO") -> 62 | H42: =COUNTIFS('Vendas - Tickets'!F:F,RESUMO_EVENTOS!A42,'Vendas - Tickets'!Q:Q,RESUMO_EVENTOS!C42,'Vendas - Tickets'!AF:AF,RESUMO_EVENTOS!D42,'Vendas - Tickets'!C:C,"Pago") -> 1 | M42: =E42-G42 -> 32 | N42: =F42-H42 -> 49
A43: Boa Vista | B43: RR | C43: 5KM | D43: XG | E43: 42 | F43: 50 | G43: =COUNTIFS('Vendas SAP'!P:P,RESUMO_EVENTOS!A43,'Vendas SAP'!J:J,RESUMO_EVENTOS!C43,'Vendas SAP'!L:L,RESUMO_EVENTOS!D43,'Vendas SAP'!O:O,"INSCRITO") -> 26 | H43: =COUNTIFS('Vendas - Tickets'!F:F,RESUMO_EVENTOS!A43,'Vendas - Tickets'!Q:Q,RESUMO_EVENTOS!C43,'Vendas - Tickets'!AF:AF,RESUMO_EVENTOS!D43,'Vendas - Tickets'!C:C,"Pago") -> 4 | M43: =E43-G43 -> 16 | N43: =F43-H43 -> 46
A44: Boa Vista | B44: RR | C44: 10KM | D44: PP | E44: 68 | F44: 8 | G44: =COUNTIFS('Vendas SAP'!P:P,RESUMO_EVENTOS!A44,'Vendas SAP'!J:J,RESUMO_EVENTOS!C44,'Vendas SAP'!L:L,RESUMO_EVENTOS!D44,'Vendas SAP'!O:O,"INSCRITO") -> 81 | H44: =COUNTIFS('Vendas - Tickets'!F:F,RESUMO_EVENTOS!A44,'Vendas - Tickets'!Q:Q,RESUMO_EVENTOS!C44,'Vendas - Tickets'!AF:AF,RESUMO_EVENTOS!D44,'Vendas - Tickets'!C:C,"Pago") -> 8 | M44: =E44-G44 -> -13 | N44: =F44-H44 -> 0
A45: Boa Vista | B45: RR | C45: 10KM | D45: P | E45: 115 | F45: 61 | G45: =COUNTIFS('Vendas SAP'!P:P,RESUMO_EVENTOS!A45,'Vendas SAP'!J:J,RESUMO_EVENTOS!C45,'Vendas SAP'!L:L,RESUMO_EVENTOS!D45,'Vendas SAP'!O:O,"INSCRITO") -> 143 | H45: =COUNTIFS('Vendas - Tickets'!F:F,RESUMO_EVENTOS!A45,'Vendas - Tickets'!Q:Q,RESUMO_EVENTOS!C45,'Vendas - Tickets'!AF:AF,RESUMO_EVENTOS!D45,'Vendas - Tickets'!C:C,"Pago") -> 34 | M45: =E45-G45 -> -28 | N45: =F45-H45 -> 27
A46: Boa Vista | B46: RR | C46: 10KM | D46: M | E46: 230 | F46: 170 | G46: =COUNTIFS('Vendas SAP'!P:P,RESUMO_EVENTOS!A46,'Vendas SAP'!J:J,RESUMO_EVENTOS!C46,'Vendas SAP'!L:L,RESUMO_EVENTOS!D46,'Vendas SAP'!O:O,"INSCRITO") -> 201 | H46: =COUNTIFS('Vendas - Tickets'!F:F,RESUMO_EVENTOS!A46,'Vendas - Tickets'!Q:Q,RESUMO_EVENTOS!C46,'Vendas - Tickets'!AF:AF,RESUMO_EVENTOS!D46,'Vendas - Tickets'!C:C,"Pago") -> 16 | M46: =E46-G46 -> 29 | N46: =F46-H46 -> 154
A47: Boa Vista | B47: RR | C47: 10KM | D47: G | E47: 133 | F47: 142 | G47: =COUNTIFS('Vendas SAP'!P:P,RESUMO_EVENTOS!A47,'Vendas SAP'!J:J,RESUMO_EVENTOS!C47,'Vendas SAP'!L:L,RESUMO_EVENTOS!D47,'Vendas SAP'!O:O,"INSCRITO") -> 98 | H47: =COUNTIFS('Vendas - Tickets'!F:F,RESUMO_EVENTOS!A47,'Vendas - Tickets'!Q:Q,RESUMO_EVENTOS!C47,'Vendas - Tickets'!AF:AF,RESUMO_EVENTOS!D47,'Vendas - Tickets'!C:C,"Pago") -> 5 | M47: =E47-G47 -> 35 | N47: =F47-H47 -> 137
A48: Boa Vista | B48: RR | C48: 10KM | D48: GG | E48: 45 | F48: 12 | G48: =COUNTIFS('Vendas SAP'!P:P,RESUMO_EVENTOS!A48,'Vendas SAP'!J:J,RESUMO_EVENTOS!C48,'Vendas SAP'!L:L,RESUMO_EVENTOS!D48,'Vendas SAP'!O:O,"INSCRITO") -> 23 | H48: =COUNTIFS('Vendas - Tickets'!F:F,RESUMO_EVENTOS!A48,'Vendas - Tickets'!Q:Q,RESUMO_EVENTOS!C48,'Vendas - Tickets'!AF:AF,RESUMO_EVENTOS!D48,'Vendas - Tickets'!C:C,"Pago") -> 1 | M48: =E48-G48 -> 22 | N48: =F48-H48 -> 11
A49: Boa Vista | B49: RR | C49: 10KM | D49: XG | E49: 21 | F49: 12 | G49: =COUNTIFS('Vendas SAP'!P:P,RESUMO_EVENTOS!A49,'Vendas SAP'!J:J,RESUMO_EVENTOS!C49,'Vendas SAP'!L:L,RESUMO_EVENTOS!D49,'Vendas SAP'!O:O,"INSCRITO") -> 9 | H49: =COUNTIFS('Vendas - Tickets'!F:F,RESUMO_EVENTOS!A49,'Vendas - Tickets'!Q:Q,RESUMO_EVENTOS!C49,'Vendas - Tickets'!AF:AF,RESUMO_EVENTOS!D49,'Vendas - Tickets'!C:C,"Pago") -> 1 | M49: =E49-G49 -> 12 | N49: =F49-H49 -> 11
A50: Kids - Manaus | B50: AM | C50: 5KM | D50: PP | G50: =COUNTIFS('Vendas 2026 - APP'!O:O,RESUMO_EVENTOS!A50,'Vendas 2026 - APP'!H:H,RESUMO_EVENTOS!C50,'Vendas 2026 - APP'!J:J,RESUMO_EVENTOS!D50,'Vendas 2026 - APP'!M:M,"INSCRITO") -> 0 | H50: =COUNTIFS('Vendas - Tickets'!Z:Z,RESUMO_EVENTOS!A50,'Vendas - Tickets'!Q:Q,RESUMO_EVENTOS!C50,'Vendas - Tickets'!AE:AE,RESUMO_EVENTOS!D50,'Vendas - Tickets'!C:C,"Pago") -> 0 | M50: =E50-G50 -> 0 | N50: =F50-H50 -> 0
A51: Kids - Manaus | B51: AM | C51: 5KM | D51: P | G51: =COUNTIFS('Vendas 2026 - APP'!O:O,RESUMO_EVENTOS!A51,'Vendas 2026 - APP'!H:H,RESUMO_EVENTOS!C51,'Vendas 2026 - APP'!J:J,RESUMO_EVENTOS!D51,'Vendas 2026 - APP'!M:M,"INSCRITO") -> 0 | H51: =COUNTIFS('Vendas - Tickets'!Z:Z,RESUMO_EVENTOS!A51,'Vendas - Tickets'!Q:Q,RESUMO_EVENTOS!C51,'Vendas - Tickets'!AE:AE,RESUMO_EVENTOS!D51,'Vendas - Tickets'!C:C,"Pago") -> 0 | M51: =E51-G51 -> 0 | N51: =F51-H51 -> 0
...

Sheet Vendas SAP
A1: DATA | B1: HORA | C1: CPF | D1: ID_CLIENTE | E1: NOME | F1: EMAIL | G1: TELEFONE | H1: DATA_NASCIMENTO | I1: CATEGORIA | J1: MODALIDADE | K1: GENERO | L1: TAMANHO | M1: TIPO_PAGAMENTO | N1: VALOR | O1: STATUS_PAGAMENTO | P1: EVENTO_ID
A2: 46144 | B2: 074750 | C2: 72040009272 | D2: 0001654888 | E2: ELIANDRO DRUMOND DE CARVALHO | F2: eliandrodrumod@hotmail.com | H2: 27830 | I2: GERAL | J2: 5KM | K2: F | L2: M | M2: CB | N2: 129.9 | O2: INSCRITO | P2: Porto Velho
A3: 46141 | B3: 090810 | C3: 11458080854 | D3: 0001590226 | E3: POLLYANA DE SOUZA BASTOS | F3: pollyana.bastos@hotmail.com | H3: 25859 | I3: GERAL | J3: 5KM | K3: M | L3: M | M3: PIX | N3: 149.9 | O3: INSCRITO | P3: Manaus
A4: 46142 | B4: 200420 | C4: 86047124291 | D4: 0001297093 | E4: KELLYANA RODRIGUES MOURA | F4: kellymcoelho@hotmail.com | H4: 31372 | I4: GERAL | J4: 5KM | K4: M | L4: P | M4: PIX | N4: 129.9 | O4: INSCRITO | P4: Manaus
A5: 46141 | B5: 131231 | C5: 02727186290 | D5: 0003075975 | E5: KARINA DO NASCIMENTO ROQUE | F5: karinaroque28@icloud.com | H5: 34945 | I5: GERAL | J5: 5KM | K5: M | L5: G | M5: PIX | N5: 149.9 | O5: INSCRITO | P5: Manaus
A6: 46147 | B6: 092458 | C6: 77553268291 | D6: 0001245137 | E6: ADRINY MAYARA PIRES DO CARMO | F6: adrinymaypires@gmail.com | H6: 32157 | I6: GERAL | J6: 10KM | K6: M | L6: G | M6: PIX | N6: 149.9 | O6: INSCRITO | P6: Manaus
A7: 46147 | B7: 083903 | C7: 90525566287 | D7: 0001660865 | E7: EDILENE DA SILVA LOPES | F7: edyllene92@gmail.com | H7: 39577 | I7: GERAL | J7: 5KM | K7: M | L7: M | M7: PIX | N7: 149.9 | O7: INSCRITO | P7: Porto Velho
